[
  {
    "test_name": "健康檢查",
    "success": false,
    "details": "請求失敗: HTTPConnectionPool(host='localhost', port=5000): Max retries exceeded with url: /api/powerautomation/health (Caused by NewConnectionError('<urllib3.connection.HTTPConnection object at 0x7fdd95e74150>: Failed to establish a new connection: [Errno 111] Connection refused'))",
    "timestamp": "2025-06-23T00:21:16.181828",
    "response_data": null
  },
  {
    "test_name": "系統狀態檢查",
    "success": false,
    "details": "請求失敗: HTTPConnectionPool(host='localhost', port=5000): Max retries exceeded with url: /api/powerautomation/status (Caused by NewConnectionError('<urllib3.connection.HTTPConnection object at 0x7fdd95e76450>: Failed to establish a new connection: [Errno 111] Connection refused'))",
    "timestamp": "2025-06-23T00:21:16.183168",
    "response_data": null
  },
  {
    "test_name": "系統啟動",
    "success": false,
    "details": "請求失敗: HTTPConnectionPool(host='localhost', port=5000): Max retries exceeded with url: /api/powerautomation/start (Caused by NewConnectionError('<urllib3.connection.HTTPConnection object at 0x7fdd95e74190>: Failed to establish a new connection: [Errno 111] Connection refused'))",
    "timestamp": "2025-06-23T00:21:16.184188",
    "response_data": null
  },
  {
    "test_name": "TRAE狀態檢查",
    "success": false,
    "details": "請求失敗: HTTPConnectionPool(host='localhost', port=5000): Max retries exceeded with url: /api/powerautomation/trae/status (Caused by NewConnectionError('<urllib3.connection.HTTPConnection object at 0x7fdd95e849d0>: Failed to establish a new connection: [Errno 111] Connection refused'))",
    "timestamp": "2025-06-23T00:21:16.185227",
    "response_data": null
  },
  {
    "test_name": "TRAE消息發送",
    "success": false,
    "details": "請求失敗: HTTPConnectionPool(host='localhost', port=5000): Max retries exceeded with url: /api/powerautomation/trae/send (Caused by NewConnectionError('<urllib3.connection.HTTPConnection object at 0x7fdd95e86e10>: Failed to establish a new connection: [Errno 111] Connection refused'))",
    "timestamp": "2025-06-23T00:21:16.186262",
    "response_data": null
  },
  {
    "test_name": "TRAE數據同步",
    "success": false,
    "details": "請求失敗: HTTPConnectionPool(host='localhost', port=5000): Max retries exceeded with url: /api/powerautomation/trae/sync (Caused by NewConnectionError('<urllib3.connection.HTTPConnection object at 0x7fdd95e95310>: Failed to establish a new connection: [Errno 111] Connection refused'))",
    "timestamp": "2025-06-23T00:21:16.187284",
    "response_data": null
  },
  {
    "test_name": "Manus連接",
    "success": false,
    "details": "請求失敗: HTTPConnectionPool(host='localhost', port=5000): Max retries exceeded with url: /api/powerautomation/manus/connect (Caused by NewConnectionError('<urllib3.connection.HTTPConnection object at 0x7fdd95e97610>: Failed to establish a new connection: [Errno 111] Connection refused'))",
    "timestamp": "2025-06-23T00:21:16.188465",
    "response_data": null
  },
  {
    "test_name": "Manus任務列表",
    "success": false,
    "details": "請求失敗: HTTPConnectionPool(host='localhost', port=5000): Max retries exceeded with url: /api/powerautomation/manus/tasks (Caused by NewConnectionError('<urllib3.connection.HTTPConnection object at 0x7fdd95e86510>: Failed to establish a new connection: [Errno 111] Connection refused'))",
    "timestamp": "2025-06-23T00:21:16.189522",
    "response_data": null
  },
  {
    "test_name": "對話分析",
    "success": false,
    "details": "請求失敗: HTTPConnectionPool(host='localhost', port=5000): Max retries exceeded with url: /api/powerautomation/analyze (Caused by NewConnectionError('<urllib3.connection.HTTPConnection object at 0x7fdd95e84590>: Failed to establish a new connection: [Errno 111] Connection refused'))",
    "timestamp": "2025-06-23T00:21:16.190458",
    "response_data": null
  },
  {
    "test_name": "智能介入",
    "success": false,
    "details": "請求失敗: HTTPConnectionPool(host='localhost', port=5000): Max retries exceeded with url: /api/powerautomation/intervene (Caused by NewConnectionError('<urllib3.connection.HTTPConnection object at 0x7fdd95e76b50>: Failed to establish a new connection: [Errno 111] Connection refused'))",
    "timestamp": "2025-06-23T00:21:16.191383",
    "response_data": null
  },
  {
    "test_name": "倉庫列表",
    "success": false,
    "details": "請求失敗: HTTPConnectionPool(host='localhost', port=5000): Max retries exceeded with url: /api/powerautomation/repositories (Caused by NewConnectionError('<urllib3.connection.HTTPConnection object at 0x7fdd95e97e50>: Failed to establish a new connection: [Errno 111] Connection refused'))",
    "timestamp": "2025-06-23T00:21:16.192280",
    "response_data": null
  },
  {
    "test_name": "系統自檢",
    "success": false,
    "details": "請求失敗: HTTPConnectionPool(host='localhost', port=5000): Max retries exceeded with url: /api/powerautomation/test (Caused by NewConnectionError('<urllib3.connection.HTTPConnection object at 0x7fdd95e9e390>: Failed to establish a new connection: [Errno 111] Connection refused'))",
    "timestamp": "2025-06-23T00:21:16.193206",
    "response_data": null
  }
]